Workbook

Sheet Automotive
A1: Full Name | B1: First Name | C1: Last Name | D1: Job Title | E1: Seniority Level | F1: Seniority Rank | G1: Lead Score | H1: Opportunity Score | I1: Company Name | J1: Industry | K1: Location | L1: Company Domain | M1: LinkedIn Profile | N1: Phone | O1: Email/Gmail | P1: Follow Up 1 | Q1: Follow Up 2 | R1: Follow Up 3 | S1: Follow Up 4 | T1: Follow Up 5 | U1: Email 1 | V1: Email 2 | W1: Email 3 | X1: Email 4 | Y1: Email 5 | Z1: Cold Call 1 | AA1: Cold Call 2 | AB1: Cold Call 3 | AC1: Meeting | AD1: RFQ | AE1: Quote | AF1: Won | AG1: Lost | AH1: Outcome Status | AI1: Rejection Reason | AJ1: Interest Reason | AK1: Notes | AL1: First Contact | AM1: Last Contact | AN1: Next Follow-up | AO1: Lead Warmth Level | AP1: Priority | AQ1: Recommended Channel | AR1: Current Stage | AS1: Value Proposition | AT1: Pain Point
A2: Djordje Stevanovic | B2: Djordje | C2: Stevanovic | D2: Group Chief Procurement Officer | E2: C-Level | F2: 1 | G2: A+ | H2: 100 | I2: Coesia S.p.A. | J2: Automotive | K2: Bologna, Emilia-Romagna, Italy | L2: coesia.com | M2: https://www.linkedin.com/in/djordje-stevanovic-644b282/ | P2: Enviado | AL2: 2026-07-01 | AM2: 2026-07-01
A3: Camillo Di Giulio | B3: Camillo | C3: Di Giulio | D3: Chief Procurement Officer | E3: C-Level | F3: 1 | G3: A+ | H3: 100 | I3: Ferroli Group | J3: Automotive | K3: Bologna, Emilia-Romagna, Italy | L3: ferroli.com | M3: https://www.linkedin.com/in/camillodigiulio/ | AD3: Hecho | AH3: RFQ | AM3: 2026-07-01
A4: Shashi Gupta | B4: Shashi | C4: Gupta | D4: Chief Procurement Officer - Wiring Harness Division | E4: C-Level | F4: 1 | G4: A+ | H4: 100 | I4: Samvardhana Motherson International Ltd. | J4: Automotive | K4: Delhi, India | L4: smil.co.in | M4: https://www.linkedin.com/in/shashi-gupta-b675324/ | AH4: Won | AK4: cerrado
A5: Mostafa Badawy | B5: Mostafa | C5: Badawy | D5: Chief Software Engineer | E5: C-Level | F5: 1 | G5: B | H5: 65 | I5: Valeo | J5: Automotive | K5: الجيزة الجيزة مصر | L5: valeo.com | M5: https://www.linkedin.com/in/mostafa-badawy-b5034088/ | AO5: Caliente | AP5: Alta | AQ5: Email
A6: Pierre Baudoin | B6: Pierre | C6: Baudoin | D6: Group Purchasing Segment Director - Plastic Aspect Parts & CDA BG Plastics Commodity Manager | E6: Director | F6: 4 | G6: A+ | H6: 100 | I6: Valeo | J6: Automotive | K6: Paris, Île-de-France, France | L6: valeo.com | M6: https://www.linkedin.com/in/pierre-baudoin-93ba00107/
A7: Satish Tanwar | B7: Satish | C7: Tanwar | D7: DGM & Head - Quality Excellence, SQA, New Product Development, APQP, PFMEA and Problem Solving | E7: Head | F7: 5 | G7: B+ | H7: 76 | I7: International tractors limited | J7: Automotive | K7: Noida, Uttar Pradesh, India | L7: sonalika.com | M7: https://www.linkedin.com/in/satish-tanwar-ba1533172/
A8: Gabriel Rosko | B8: Gabriel | C8: Rosko | D8: Purchasing Commodity Manager | E8: Manager | F8: 6 | G8: A+ | H8: 94 | I8: Adient | J8: Automotive | K8: Pluak Daeng, Rayong, Thailand | L8: adient.com | M8: https://www.linkedin.com/in/gabriel-rosko-75577747/
A9: Linda Bliznáková | B9: Linda | C9: Bliznáková | D9: Global Commodity Manager Fasteners | E9: Manager | F9: 6 | G9: A+ | H9: 94 | I9: Adient | J9: Automotive | K9: Bratislava Metropolitan Area | L9: adient.com | M9: https://www.linkedin.com/in/linda-blizn%c3%a1kov%c3%a1-6317378b/
A10: Naima Boudjelida | B10: Naima | C10: Boudjelida | D10: Commodity Manager Packaging EMEA | E10: Manager | F10: 6 | G10: A+ | H10: 94 | I10: Adient | J10: Automotive | K10: Strasbourg, Grand Est, France | L10: adient.com | M10: https://www.linkedin.com/in/naima-boudjelida-4354b9163/
A11: Pavel Ružička | B11: Pavel | C11: Ružička | D11: Commodity Manager TRIM EMEA | E11: Manager | F11: 6 | G11: A+ | H11: 94 | I11: Adient | J11: Automotive | K11: Bratislava, Slovakia | L11: adient.com | M11: https://www.linkedin.com/in/ruzickapavel/
A12: Salatiel Mateus, MBA | B12: Salatiel | C12: Mateus | D12: Senior Commodity Manager - North America | E12: Manager | F12: 6 | G12: A+ | H12: 94 | I12: Adient | J12: Automotive | K12: Detroit Metropolitan Area, United States | L12: adient.com | M12: https://www.linkedin.com/in/salatiel-mateus-filho-mba/
A13: Iulian Zediu | B13: Iulian | C13: Zediu | D13: Senior Supplier Development Engineer - Local Manager | E13: Manager | F13: 6 | G13: A+ | H13: 100 | I13: Allison Off-Highway Drive & Motion Systems | J13: Automotive | K13: Reggio nell'Emilia, Emilia-Romagna, Italy | L13: allisonoffhighway.com | M13: https://www.linkedin.com/in/iulian-zediu-60abb740/
A14: Burak Macit | B14: Burak | C14: Macit | D14: Purchasing Manager Europe - Airbag | E14: Manager | F14: 6 | G14: A+ | H14: 94 | I14: Autoliv | J14: Automotive | K14: Istanbul, Turkey | L14: autoliv.com | M14: https://www.linkedin.com/in/burak-macit-94a9184a/
A15: Tim Popa | B15: Tim | C15: Popa | D15: Senior Commodity Manager - Strategic & Sourcing | E15: Manager | F15: 6 | G15: A+ | H15: 94 | I15: Autoliv | J15: Automotive | K15: Macomb, Michigan, United States | L15: autoliv.com | M15: https://www.linkedin.com/in/tim-popa-12506011/
A16: Rathesh KR | B16: Rathesh | C16: KR | D16: Global Commodity Manager | E16: Manager | F16: 6 | G16: A+ | H16: 94 | I16: Autoliv India | J16: Automotive | K16: Greater Bengaluru Area, India | L16: autoliv.com | M16: https://www.linkedin.com/in/rathesh-kr-9b74065a/
A17: Günhan Tekin | B17: Günhan | C17: Tekin | D17: Purchasing Manager | Raw Material | Tooling | Indirect Service | E17: Manager | F17: 6 | G17: A+ | H17: 100 | I17: Beyçelik Gestamp | J17: Automotive | K17: Bursa, Turkey | L17: beycelikgestamp.com.tr | M17: https://www.linkedin.com/in/günhan-tekin-03612869/
... A123: Martha Ocádiz | B123: Martha | C123: Ocádiz | D123: Global Strategic Sourcing Manager - Category Manager. Harnesses - Cables & Seats | E123: Manager | F123: 6 | G123: A+ | H123: 94 | I123: Polaris Inc. | J123: Automotive | K123: Nuevo León, Mexico | L123: polaris.com | M123: https://www.linkedin.com/in/martha-ocadiz/
A124: Bramantyo - | B124: Bramantyo | D124: Procurement Manager | E124: Manager | F124: 6 | G124: A+ | H124: 94 | I124: PT Toyota Motor Manufacturing Indonesia | J124: Automotive | K124: Indonesia | L124: toyota.co.id | M124: https://www.linkedin.com/in/bramantyo-a487a219/
A125: Hari Bala Manoj S | B125: Hari | C125: S | D125: Assistant Manager - Buyer Paints & Sealants | E125: Manager | F125: 6 | G125: A+ | H125: 94 | I125: Renault Nissan Technology & Business Centre India | J125: Automotive | K125: Tiruchirappalli, Tamil Nadu, India | L125: rntbci.in | M125: https://www.linkedin.com/in/hari-bala-manoj-s-67079623/
A126: Ravikumar Parasa | B126: Ravikumar | C126: Parasa | D126: Procurement Manager | E126: Manager | F126: 6 | G126: A+ | H126: 94 | I126: Renault Nissan Technology & Business Centre India | J126: Automotive | K126: Chennai, Tamil Nadu, India | L126: rntbci.in | M126: https://www.linkedin.com/in/pv-ravikumar04/
A127: Ercan Mutlu | B127: Ercan | C127: Mutlu | D127: Regional Supplier Purchasing Manager | E127: Manager | F127: 6 | G127: A+ | H127: 94 | I127: Renault-Nissan-Mitsubishi | J127: Automotive | K127: Turkey | L127: alliance-2022.com | M127: https://www.linkedin.com/in/ercan-mutlu-87a67966/
A128: Paola Schipitoski Rohde Buffa | B128: Paola | C128: Buffa | D128: Project Purchasing Manager | E128: Manager | F128: 6 | G128: A+ | H128: 94 | I128: Renault-Nissan-Mitsubishi | J128: Automotive | K128: São José dos Pinhais, Paraná, Brazil | L128: alliance-2022.com | M128: https://www.linkedin.com/in/paola-schipitoski-rohde-buffa-6b472826/
A129: Erica McBride-Rapp (Barbon) MS SCM, CPSM | B129: Erica | C129: CPSM | D129: Senior Purchasing Manager | E129: Manager | F129: 6 | G129: A+ | H129: 94 | I129: Rivian | J129: Automotive | K129: Philadelphia, Pennsylvania, United States | L129: rivian.com | M129: https://www.linkedin.com/in/erica-mcbride-rapp-barbon-ms-scm-cpsm-468a477b/
A130: Francisco Fernández | B130: Francisco | C130: Fernández | D130: Lead Purchasing Manager, Interiors | E130: Manager | F130: 6 | G130: A+ | H130: 94 | I130: Rivian | J130: Automotive | K130: Milpitas, California, United States | L130: rivian.com | M130: https://www.linkedin.com/in/francisco-fernández-1499b61a/
A131: Ivy Li | B131: Ivy | C131: Li | D131: Lead Purchasing Manager | E131: Manager | F131: 6 | G131: A+ | H131: 94 | I131: Rivian | J131: Automotive | K131: San Francisco Bay Area | L131: rivian.com | M131: https://www.linkedin.com/in/ivylisy/
A132: Manish Deshmukh | B132: Manish | C132: Deshmukh | D132: Lead Purchasing Manager | E132: Manager | F132: 6 | G132: A+ | H132: 94 | I132: Rivian | J132: Automotive | K132: Plymouth, Michigan, United States | L132: rivian.com | M132: https://www.linkedin.com/in/manish-deshmukh-391aab52/
A133: Panzavolta Mattia | B133: Panzavolta | C133: Mattia | D133: Purchasing Manager | E133: Manager | F133: 6 | G133: A+ | H133: 94 | I133: RONCUZZI S.R.L. | J133: Automotive | K133: Faenza, Emilia-Romagna, Italy | L133: roncuzzi.com | M133: https://www.linkedin.com/in/panzavolta-mattia-5817118b/
A134: Alessandro Del Din | B134: Alessandro | C134: Del Din | D134: Purchasing Global Commodity Manager Tires, EMEA Commodity Manager Steering | E134: Manager | F134: 6 | G134: A+ | H134: 94 | I134: Stellantis | J134: Automotive | K134: Greater Turin Metropolitan Area | L134: stellantis.com | M134: https://www.linkedin.com/in/alessandro-del-din-1a9a5863/
A135: Avinash chandrasekar | B135: Avinash | C135: chandrasekar | D135: Sourcing Manager - India & Asia Pacific | E135: Manager | F135: 6 | G135: A+ | H135: 94 | I135: Stellantis | J135: Automotive | K135: Chennai, Tamil Nadu, India | L135: stellantis.com | M135: https://www.linkedin.com/in/avinash-chandrasekar-71292323/
A136: Delphine MONTEIRO FEBVIN | B136: Delphine | C136: FEBVIN | D136: Purchasing Manager Functional Exterior Plastic Parts | E136: Manager | F136: 6 | G136: A+ | H136: 100 | I136: Stellantis | J136: Automotive | K136: Poissy, Île-de-France, France | L136: stellantis.com | M136: https://www.linkedin.com/in/delphine-monteiro-febvin-85948110/
... A170: Petre Bogdan Nicoara | B170: Petre | C170: Nicoara | D170: Serial Purchasing Manager Europe | E170: Manager | F170: 6 | G170: A+ | H170: 94 | I170: Webasto Group | J170: Automotive | K170: Arad, Romania | L170: webasto.com | M170: https://www.linkedin.com/in/bogdannicoara/
A171: Adrián García Ortiz | B171: Adrián | C171: Ortiz | D171: Commodity Manager | E171: Manager | F171: 6 | G171: A+ | H171: 94 | I171: Yanfeng | J171: Automotive | K171: Querétaro, Querétaro, Mexico | M171: https://www.linkedin.com/in/adrián-garcía-ortiz-5165412a/
A172: Anikó Richter | B172: Anikó | C172: Richter | D172: YFI Logistics Procurement Manager EMEA | E172: Manager | F172: 6 | G172: A+ | H172: 94 | I172: Yanfeng | J172: Automotive | K172: Sopron, Győr-Moson-Sopron, Hungary | M172: https://www.linkedin.com/in/anik%c3%b3-richter-37b589169/
A173: Carey Caswell | B173: Carey | C173: Caswell | D173: Senior Procurement Manager — Plastics Tooling NA/EMEA | E173: Manager | F173: 6 | G173: A+ | H173: 100 | I173: Yanfeng | J173: Automotive | K173: Holland, Michigan, United States | M173: https://www.linkedin.com/in/carey-caswell-01720113/
A174: Jose Baptista | B174: Jose | C174: Baptista | D174: Procurement Manager - IT&Telco, Packaging, Security, Scrap, Travel and Fleet - EMEA | E174: Manager | F174: 6 | G174: A+ | H174: 94 | I174: Yazaki Europe Middle East and Africa | J174: Automotive | K174: Aveiro, Aveiro, Portugal | L174: yazaki-europe.com | M174: https://www.linkedin.com/in/jose-baptista-b8555272/
A175: Marco Palmitessa | B175: Marco | C175: Palmitessa | D175: Purchasing Manager | E175: Manager | F175: 6 | G175: A+ | H175: 94 | I175: Yazaki Europe Middle East and Africa | J175: Automotive | K175: Rivoli, Piedmont, Italy | L175: yazaki-europe.com | M175: https://www.linkedin.com/in/marco-palmitessa-1439762/
A176: Achin Sharma | B176: Achin | C176: Sharma | D176: Purchasing Manager | E176: Manager | F176: 6 | G176: A+ | H176: 94 | I176: Yazaki India Private Limited | J176: Automotive | K176: Bengaluru, Karnataka, India | M176: https://www.linkedin.com/in/achin-sharma-a614a0a1/
A177: Érica Oliveira | B177: Érica | C177: Oliveira | D177: Purchasing Manager | E177: Manager | F177: 6 | G177: A+ | H177: 94 | I177: Yazaki Mercosul | J177: Automotive | K177: Tatuí, São Paulo, Brazil | L177: yazaki-group.com | M177: https://www.linkedin.com/in/érica-oliveira-godói-b1424323/
A178: Adrian Muñoz | B178: Adrian | C178: Muñoz | D178: Senior Global Commodity Manager | Stampings | Cutting & Bending Medium/Large | E178: Manager | F178: 6 | G178: A+ | H178: 94 | I178: ZF Group | J178: Automotive | K178: Madrid, Spain | L178: zf.com | M178: https://www.linkedin.com/in/adrianbouzo/
...

Sheet Pharmaceutical
A1: Full Name | B1: First Name | C1: Last Name | D1: Job Title | E1: Seniority Level | F1: Seniority Rank | G1: Lead Score | H1: Opportunity Score | I1: Company Name | J1: Industry | K1: Location | L1: Company Domain | M1: LinkedIn Profile | N1: Phone | O1: Email/Gmail | P1: Follow Up 1 | Q1: Follow Up 2 | R1: Follow Up 3 | S1: Follow Up 4 | T1: Follow Up 5 | U1: Email 1 | V1: Email 2 | W1: Email 3 | X1: Email 4 | Y1: Email 5 | Z1: Cold Call 1 | AA1: Cold Call 2 | AB1: Cold Call 3 | AC1: Meeting | AD1: RFQ | AE1: Quote | AF1: Won | AG1: Lost | AH1: Outcome Status | AI1: Rejection Reason | AJ1: Interest Reason | AK1: Notes | AL1: First Contact | AM1: Last Contact | AN1: Next Follow-up
A2: Richard Jones | B2: Richard | C2: Jones | D2: Senior Director, Forward Deployed Principal Software Engineer | E2: Director | F2: 4 | G2: C+ | H2: 56 | I2: Pfizer | J2: Pharmaceutical | K2: Greater Brighton and Hove Area | L2: pfizer.com | M2: https://www.linkedin.com/in/richard-jones-8b7aa53/
A3: Burak Aydınalp | B3: Burak | C3: Aydınalp | D3: Direct Materials Procurement Manager | E3: Manager | F3: 6 | G3: A | H3: 87 | I3: Abdi Ibrahim Pharmaceuticals | J3: Pharmaceutical | K3: Istanbul, Istanbul, Türkiye | L3: abdiibrahim.com.tr | M3: https://www.linkedin.com/in/burak-ayd%c4%b1nalp-732a3354/
A4: Hazal Pala Özdemir | B4: Hazal | C4: Özdemir | D4: Direct Materials Procurement Manager | E4: Manager | F4: 6 | G4: A | H4: 87 | I4: Abdi Ibrahim Pharmaceuticals | J4: Pharmaceutical | K4: Istanbul, Turkey | L4: abdiibrahim.com.tr | M4: https://www.linkedin.com/in/hazal-pala-%c3%b6zdemir-31979586/
A5: Uğur Ahmet Eder | B5: Uğur | C5: Eder | D5: Purchasing Manager - International Markets and Services Purchasing Manager Algeria & Kazakhstan | E5: Manager | F5: 6 | G5: A | H5: 87 | I5: Abdi Ibrahim Pharmaceuticals | J5: Pharmaceutical | K5: Istanbul, Turkey | L5: abdiibrahim.com.tr | M5: https://www.linkedin.com/in/u%c4%9fur-ahmet-eder-94193284/
A6: Krunal Joshi | B6: Krunal | C6: Joshi | D6: Purchasing Manager | E6: Manager | F6: 6 | G6: A | H6: 87 | I6: Alembic Pharmaceuticals Limited | J6: Pharmaceutical | K6: Vadodara, Gujarat, India | L6: alembic-india.com | M6: https://www.linkedin.com/in/krunal-joshi-941a4528/
A7: Sharon DeFeo | B7: Sharon | C7: DeFeo | D7: Global Procurement Manager | E7: Manager | F7: 6 | G7: A | H7: 87 | I7: Allergan | J7: Pharmaceutical | K7: New York City Metropolitan Area | L7: abbvie.com | M7: https://www.linkedin.com/in/sharondefeo/
A8: KIRANKUMAR NAYEE | B8: Kirankumar | C8: Nayee | D8: Procurement Manager | E8: Manager | F8: 6 | G8: A | H8: 87 | I8: Amneal Pharmaceuticals | J8: Pharmaceutical | K8: Ahmedabad, Gujarat, India | L8: amneal.com | M8: https://www.linkedin.com/in/kirankumar-nayee-1607b453/
A9: Claire Campenon | B9: Claire | C9: Campenon | D9: Packaging Purchasing Manager | E9: Manager | F9: 6 | G9: A | H9: 87 | I9: Arkopharma | J9: Pharmaceutical | K9: Nice, Provence-Alpes-Côte d'Azur, France | L9: arkopharma.com | M9: https://www.linkedin.com/in/claire-campenon-1919423a/
A10: Carolina P. | B10: Carolina | C10: P. | D10: Purchasing Manager | E10: Manager | F10: 6 | G10: A | H10: 87 | I10: Arnet Pharmaceutical Corp | J10: Pharmaceutical | K10: Fort Lauderdale, Florida, United States | L10: arnetusa.com | M10: https://www.linkedin.com/in/carolina-p-30428417/
A11: Simon Marshall, FCIPS | B11: Simon | C11: FCIPS | D11: Global Procurement Manager | E11: Manager | F11: 6 | G11: A | H11: 87 | I11: AstraZeneca | J11: Pharmaceutical | K11: Derbyshire, England, United Kingdom | L11: astrazeneca.com | M11: https://www.linkedin.com/in/simon-marshall-fcips-2a18a422/
A12: Steve Madeley | B12: Steve | C12: Madeley | D12: Sourcing manager | E12: Manager | F12: 6 | G12: A | H12: 87 | I12: AstraZeneca | J12: Pharmaceutical | K12: Greater Manchester, England, United Kingdom | L12: astrazeneca.com | M12: https://www.linkedin.com/in/steve-madeley-b55a3926/
A13: Cesare Zinanni | B13: Cesare | C13: Zinanni | D13: Purchasing Manager | E13: Manager | F13: 6 | G13: A | H13: 87 | I13: Boehringer Ingelheim | J13: Pharmaceutical | K13: Montevarchi, Toscana, Italia | L13: boehringer-ingelheim.com | M13: https://www.linkedin.com/in/cesare-zinanni-02bb80/
... A61: Jay Prakash | B61: Jay | C61: Prakash | D61: Global Strategic Sourcing Manager Packaging Materials | E61: Manager | F61: 6 | G61: A | H61: 87 | I61: SUN PHARMA | J61: Pharmaceutical | K61: Mumbai, Maharashtra, India | L61: sunpharma.com | M61: https://www.linkedin.com/in/jay-prakash-1327b37b/
A62: Mohamed Samir Shokry Ali | B62: Mohamed | C62: Ali | D62: Procurement Manager (Supply Chain) | E62: Manager | F62: 6 | G62: A | H62: 87 | I62: Sunny Pharmaceutical | J62: Pharmaceutical | K62: Egypt, Egypt | M62: https://www.linkedin.com/in/mohamed-samir-shokry-ali-7ab907bb/
A63: Diana Alpuche | B63: Diana | C63: Alpuche | D63: Strategic Procurement Manager - Category Leader | E63: Manager | F63: 6 | G63: A | H63: 87 | I63: Takeda | J63: Pharmaceutical | K63: Mexico City, Ciudad de México, Mexico | L63: takeda.com | M63: https://www.linkedin.com/in/diana-alpuche-3a0b581b/
A64: Gustavo Oliveira | B64: Gustavo | C64: Oliveira | D64: Senior Strategic Procurement Manager - LATAM | E64: Manager | F64: 6 | G64: A | H64: 87 | I64: Takeda | J64: Pharmaceutical | K64: São Paulo, São Paulo, Brazil | L64: takeda.com | M64: https://www.linkedin.com/in/gustavo-oliveira-22a2072b/
A65: David Loudner | B65: David | C65: Loudner | D65: Global Strategic Sourcing Manager | E65: Manager | F65: 6 | G65: A | H65: 87 | I65: West Pharmaceutical Services | J65: Pharmaceutical | K65: Greater Tampa Bay Area, United States | L65: westpharma.com | M65: https://www.linkedin.com/in/david-loudner-1057641b/
A66: Orla King | B66: Orla | C66: King | D66: Site Procurement Manager | E66: Manager | F66: 6 | G66: A | H66: 87 | I66: West Pharmaceutical Services | J66: Pharmaceutical | K66: Dublin, County Dublin, Ireland | L66: westpharma.com | M66: https://www.linkedin.com/in/orla-king-01759322/
A67: Lucas Lalouani | B67: Lucas | C67: Lalouani | D67: Packaging Group Lead Buyer Pharma / Cosmetics | E67: Lead | F67: 7 | G67: A | H67: 83 | I67: FAREVA | J67: Pharmaceutical | K67: France | L67: fareva.com | M67: https://www.linkedin.com/in/lucas-lalouani-59b5a1123/
A68: Mihaela Vučić | B68: Mihaela | C68: Vučić | D68: Lead Sourcing Specialist | E68: Lead | F68: 7 | G68: A | H68: 83 | I68: Novo Nordisk | J68: Pharmaceutical | K68: Zagreb, Zagreb, Croatia | L68: novonordisk.com | M68: https://www.linkedin.com/in/vucicmihaela168/
A69: Alexiane Tissot | B69: Alexiane | C69: Tissot | D69: Global Category Lead Buyer - Packaging, Global Procurement | E69: Lead | F69: 7 | G69: A | H69: 83 | I69: Sanofi | J69: Pharmaceutical | K69: Greater Lyon Area, France | L69: sanofi.com | M69: https://www.linkedin.com/in/alexiane-tissot-46b4729a/
A70: Ana Daniela Fernandes Guandalini | B70: Ana | C70: Guandalini | D70: Primary Packaging Global Lead Buyer CHC | E70: Lead | F70: 7 | G70: A | H70: 83 | I70: Sanofi | J70: Pharmaceutical | K70: Chattanooga, Tennessee, United States | L70: sanofi.com | M70: https://www.linkedin.com/in/ana-daniela-fernandes-guandalini-b6469b13/
A71: Laurence PLANTEROSE | B71: Laurence | C71: PLANTEROSE | D71: Global Lead Buyer Clinical Supplies - Worlwide | E71: Lead | F71: 7 | G71: A | H71: 83 | I71: Sanofi | J71: Pharmaceutical | K71: Greater Lyon Area | L71: sanofi.com | M71: https://www.linkedin.com/in/laurence-planterose-8b597311/
A72: Noha Mayhoub | B72: Noha | C72: Mayhoub | D72: Global Lead Buyer, ATME | E72: Lead | F72: 7 | G72: A | H72: 83 | I72: Sanofi | J72: Pharmaceutical | K72: Egypt | L72: sanofi.com | M72: https://www.linkedin.com/in/noha-mayhoub-593a6b53/
A73: Adrien Donati | B73: Adrien | C73: Donati | D73: Lead Buyer - Glass Raw Materials, Packaging & Special projects | E73: Lead | F73: 7 | G73: A | H73: 83 | I73: SGD Pharma | J73: Pharmaceutical | K73: France | L73: sgd-pharma.com | M73: https://www.linkedin.com/in/adrien-donati-7999a9108/
A74: Marcin Hanusewicz | B74: Marcin | C74: Hanusewicz | D74: Senior Procurement Specialist | E74: Senior | F74: 8 | G74: A | H74: 81 | I74: Adamed Pharma | J74: Pharmaceutical | K74: Warsaw Metropolitan Area | L74: adamed.com | M74: https://www.linkedin.com/in/marcin-hanusewicz-7066a82b/
... A79: Rony Varghese | B79: Rony | C79: Varghese | D79: Senior Buyer - NPI & Strategic Projects | E79: Senior | F79: 8 | G79: A | H79: 81 | I79: PCI Pharma Services | J79: Pharmaceutical | K79: Dublin, County Dublin, Ireland | L79: pci.com | M79: https://www.linkedin.com/in/rony-varghese-82402167/
A80: Marco Balacco | B80: Marco | C80: Balacco | D80: Senior Buyer and Warehouse | E80: Senior | F80: 8 | G80: A | H80: 81 | I80: Pharmaceutical Company | J80: Pharmaceutical | K80: Milan, Lombardy, Italy | M80: https://www.linkedin.com/in/marco-balacco-2511a111/
A81: Andrea Cowell | B81: Andrea | C81: Cowell | D81: Senior Procurement Specialist | E81: Senior | F81: 8 | G81: A | H81: 81 | I81: Piramal Pharma Ltd | J81: Pharmaceutical | K81: Ashington, England, United Kingdom | L81: piramalpharma.com | M81: https://www.linkedin.com/in/andrea-cowell-a33b0a29/
A82: Tunde Ogunlana (MBA, CITLS, MMIPM, CPP- ACSC, ENG) | B82: Tunde | C82: Ogunlana | D82: Senior Procurement Officer | E82: Senior | F82: 8 | G82: A | H82: 81 | I82: Swiss Pharma Limited | J82: Pharmaceutical | K82: Lagos State, Nigeria | L82: swiphanigeria.com | M82: https://www.linkedin.com/in/tunde-ogunlana-mba-citls-mmipm-cpp-acsc-eng-73b39285/
A83: Mike Lanzone | B83: Mike | C83: Lanzone | D83: Senior Buyer | E83: Senior | F83: 8 | G83: A | H83: 81 | I83: Unither Pharmaceuticals | J83: Pharmaceutical | K83: Fairport, New York, United States | L83: unither-pharma.com | M83: https://www.linkedin.com/in/mlanzone/
A84: Shawna Spahn | B84: Shawna | C84: Spahn | D84: Senior Quality Engineer | E84: Senior | F84: 8 | G84: B | H84: 61 | I84: AbbVie | J84: Pharmaceutical | K84: Cincinnati Metropolitan Area | L84: abbvie.com | M84: https://www.linkedin.com/in/shawna-spahn-6b34901a/
A85: Tracy M. Gray Fields | B85: Tracy | C85: Fields | D85: Senior Quality Engineer | E85: Senior | F85: 8 | G85: B | H85: 61 | I85: AbbVie | J85: Pharmaceutical | K85: Greater Chicago Area | L85: abbvie.com | M85: https://www.linkedin.com/in/tracy-m-gray-fields-b113338/
A86: Carlisse Abreu | B86: Carlisse | C86: Abreu | D86: Sr Principal Quality Assurance Engineer - IDAP Dry | E86: Senior | F86: 8 | G86: B | H86: 61 | I86: Eli Lilly and Company | J86: Pharmaceutical | K86: Indianapolis, Indiana, United States | L86: lilly.com | M86: https://www.linkedin.com/in/carlisse-abreu-86678625/
A87: Ilias Foufopoulos | B87: Ilias | C87: Foufopoulos | D87: Senior Quality Assurance Engineer | E87: Senior | F87: 8 | G87: B | H87: 61 | I87: Pharmathen | J87: Pharmaceutical | K87: Pallíni, Attiki, Greece | L87: pharmathen.com | M87: https://www.linkedin.com/in/ilias-foufopoulos/
A88: Mayank Kumar | B88: Mayank | C88: Kumar | D88: Senior Quality Assurance Engineer | E88: Senior | F88: 8 | G88: B | H88: 61 | I88: Translumina Therapeutics | J88: Pharmaceutical | K88: Faridabad, Haryana, India | L88: translumina.com | M88: https://www.linkedin.com/in/mayank-kumar-533609181/
A89: Ashley G. | B89: Ashley | C89: G. | D89: Senior Quality Engineer | E89: Senior | F89: 8 | G89: B | H89: 61 | I89: West Pharmaceutical Services | J89: Pharmaceutical | K89: Mesa, Arizona, United States | L89: westpharma.com | M89: https://www.linkedin.com/in/ashley-g-634a0258/
A90: Austin Nguyenphu | B90: Austin | C90: Nguyenphu | D90: Senior Quality Engineer | E90: Senior | F90: 8 | G90: B | H90: 61 | I90: West Pharmaceutical Services | J90: Pharmaceutical | K90: Phoenix, Arizona, United States | L90: westpharma.com | M90: https://www.linkedin.com/in/austin-nguyenphu-b33010112/
A91: Adam Barnhard | B91: Adam | C91: Barnhard | D91: Senior Software Engineer | E91: Senior | F91: 8 | G91: C | H91: 46 | I91: Allergan Aesthetics, an AbbVie Company | J91: Pharmaceutical | K91: Denver, Colorado, United States | L91: allerganaesthetics.com | M91: https://www.linkedin.com/in/adambarnhard/
...

Sheet Medical Devices
A1: Full Name | B1: First Name | C1: Last Name | D1: Job Title | E1: Seniority Level | F1: Seniority Rank | G1: Lead Score | H1: Opportunity Score | I1: Company Name | J1: Industry | K1: Location | L1: Company Domain | M1: LinkedIn Profile | N1: Phone | O1: Email/Gmail | P1: Follow Up 1 | Q1: Follow Up 2 | R1: Follow Up 3 | S1: Follow Up 4 | T1: Follow Up 5 | U1: Email 1 | V1: Email 2 | W1: Email 3 | X1: Email 4 | Y1: Email 5 | Z1: Cold Call 1 | AA1: Cold Call 2 | AB1: Cold Call 3 | AC1: Meeting | AD1: RFQ | AE1: Quote | AF1: Won | AG1: Lost | AH1: Outcome Status | AI1: Rejection Reason | AJ1: Interest Reason | AK1: Notes | AL1: First Contact | AM1: Last Contact | AN1: Next Follow-up
A2: Asad Nizamani | B2: Asad | C2: Nizamani | D2: Sr. Sourcing Manager (Abbott Global Procurement) | E2: Manager | F2: 6 | G2: A+ | H2: 94 | I2: Abbott | J2: Medical Devices | K2: Pakistan, Pakistan | L2: abbott.com | M2: https://www.linkedin.com/in/asad-nizamani-8172832a/
A3: Bahar Merve Soykan Betin | B3: Bahar | C3: Betin | D3: Direct Procurement Manager | E3: Manager | F3: 6 | G3: A+ | H3: 94 | I3: Abbott | J3: Medical Devices | K3: Istanbul, Turkey | L3: abbott.com | M3: https://www.linkedin.com/in/bahar-merve-soykan-betin-91871696/
A4: Jason C. | B4: Jason | C4: C. | D4: Corporate Procurement Manager - Biologics | E4: Manager | F4: 6 | G4: A+ | H4: 94 | I4: Abbott | J4: Medical Devices | K4: Greater Chicago Area, United States | L4: abbott.com | M4: https://www.linkedin.com/in/jchorazy/
A5: Maarten Petter | B5: Maarten | C5: Petter | D5: Procurement Manager Packaging | E5: Manager | F5: 6 | G5: A+ | H5: 94 | I5: Abbott | J5: Medical Devices | K5: Staphorst, Overijssel, Netherlands | L5: abbott.com | M5: https://www.linkedin.com/in/maarten-petter-81861b28/
A6: Michael Tardi | B6: Michael | C6: Tardi | D6: Global Strategic Purchasing – Procurement Manager (Reagents & Biologics) | E6: Manager | F6: 6 | G6: A+ | H6: 94 | I6: Abbott | J6: Medical Devices | K6: Greater Chicago Area | L6: abbott.com | M6: https://www.linkedin.com/in/michaeltardi/
A7: Christina Janus | B7: Christina | C7: Janus | D7: Strategic Procurement Manager, Direct Spend | E7: Manager | F7: 6 | G7: A+ | H7: 94 | I7: Ambu | J7: Medical Devices | K7: Copenhagen, Capital Region, Denmark | L7: ambu.com | M7: https://www.linkedin.com/in/christina-janus-061a2b1/
A8: Luis Aguado | B8: Luis | C8: Aguado | D8: Sr. Quality/Supplier Quality Engineer/Manager | E8: Manager | F8: 6 | G8: A+ | H8: 100 | I8: Ascensia Diabetes Care | J8: Medical Devices | K8: Dover, New Jersey, United States | L8: ascensia.com | M8: https://www.linkedin.com/in/luis-aguado-8a676935/
A9: Lyubov Dolgopolova | B9: Lyubov | C9: Dolgopolova | D9: Senior Procurement Manager | E9: Manager | F9: 6 | G9: A+ | H9: 94 | I9: Bausch + Lomb | J9: Medical Devices | K9: Moscow City, Russia | L9: bausch.com | M9: https://www.linkedin.com/in/lyubovdolgopolova/
A10: Aleksandra Brodowicz | B10: Aleksandra | C10: Brodowicz | D10: Senior Procurement Manager EMEA & APAC | E10: Manager | F10: 6 | G10: A+ | H10: 94 | I10: Baxter International Inc. | J10: Medical Devices | K10: Warsaw Metropolitan Area, Poland | L10: baxter.com | M10: https://www.linkedin.com/in/aleksandra-brodowicz-a4aa2365/
A11: Gerardo Treviño | B11: Gerardo | C11: Treviño | D11: Global Commodity Manager | E11: Manager | F11: 6 | G11: A+ | H11: 94 | I11: Baxter International Inc. | J11: Medical Devices | K11: Nuevo León, Mexico | L11: baxter.com | M11: https://www.linkedin.com/in/gerardo-treviño-5a4450101/
A12: Johnny Chinchilla | B12: Johnny | C12: Chinchilla | D12: Sr. Procurement Manager Infusion Therapies & Technologies | E12: Manager | F12: 6 | G12: A+ | H12: 94 | I12: Baxter International Inc. | J12: Medical Devices | K12: Costa Rica | L12: baxter.com | M12: https://www.linkedin.com/in/johnnychinchillacr/
A13: Claire Brossy-Laporte | B13: Claire | C13: Brossy-Laporte | D13: SG&A Procurement Manager EMEA | E13: Manager | F13: 6 | G13: A+ | H13: 94 | I13: BD | J13: Medical Devices | K13: Greater Grenoble Metropolitan Area, France | L13: bd.com | M13: https://www.linkedin.com/in/claire-brossy-laporte-b3563946/
... A195: Aurora Jiménez Vargas | B195: Aurora | C195: Vargas | D195: Quality Engineer III | E195: Engineer | F195: 10 | G195: B | H195: 64 | I195: Abbott | J195: Medical Devices | K195: San Jose, Costa Rica | L195: abbott.com | M195: https://www.linkedin.com/in/aurora-jiménez-vargas/
A196: Gundla . | B196: Gundla | D196: Manufacturing Quality Engineer | E196: Engineer | F196: 10 | G196: B | H196: 64 | I196: Abbott | J196: Medical Devices | K196: Hillsboro, Oregon, United States | L196: abbott.com | M196: https://www.linkedin.com/in/balaji-varma-gundla-/
A197: Karla Sofìa Ramírez Sánchez | B197: Karla | C197: Sánchez | D197: Quality Engineer III | E197: Engineer | F197: 10 | G197: B | H197: 64 | I197: Abbott | J197: Medical Devices | K197: San Jose, Costa Rica | L197: abbott.com | M197: https://www.linkedin.com/in/karla-ram%c3%adrez-s%c3%a1nchez-61059b96/
A198: Ritvik raj v | B198: Ritvik | C198: raj | D198: Quality Engineer | E198: Engineer | F198: 10 | G198: B | H198: 64 | I198: Abbott | J198: Medical Devices | K198: Kingsville, Texas, United States | L198: abbott.com | M198: https://www.linkedin.com/in/ritvik-raj-v-a1317621a/
A199: Simran Sankhe | B199: Simran | C199: Sankhe | D199: Operations Quality Engineer | E199: Engineer | F199: 10 | G199: B | H199: 64 | I199: Abbott | J199: Medical Devices | K199: Kilkenny, County Kilkenny, Ireland | L199: abbott.com | M199: https://www.linkedin.com/in/simran-sankhe-601437121/
A200: VamsiKiran Eruvaram | B200: VamsiKiran | C200: Eruvaram | D200: Quality Engineer | E200: Engineer | F200: 10 | G200: B | H200: 64 | I200: Abbott | J200: Medical Devices | K200: Santa Clara, California, United States | L200: abbott.com | M200: https://www.linkedin.com/in/vamsikiran-eruvaram/
A201: Andrew Singgih | B201: Andrew | C201: Singgih | D201: Principal Quality Assurance Engineer | E201: Engineer | F201: 10 | G201: B | H201: 64 | I201: Adagio Medical Inc. | J201: Medical Devices | K201: Irvine, California, United States | L201: adagiomedical.com | M201: https://www.linkedin.com/in/andrew-singgih-3766552/
A202: Jesus Anaya | B202: Jesus | C202: Anaya | D202: Quality Engineer | E202: Engineer | F202: 10 | G202: B | H202: 64 | I202: Alcon | J202: Medical Devices | K202: Chino, California, United States | L202: alcon.com | M202: https://www.linkedin.com/in/jesus-anaya-0a269a156/
A203: Sabreen S. | B203: Sabreen | C203: S. | D203: Design Quality Engineer II | E203: Engineer | F203: 10 | G203: B | H203: 64 | I203: Arthrex | J203: Medical Devices | K203: United States | L203: arthrex.com | M203: https://www.linkedin.com/in/sabreen-shaik-b7a03516a/
A204: Will Lucas | B204: Will | C204: Lucas | D204: Principal Design Quality Engineer | E204: Engineer | F204: 10 | G204: B | H204: 64 | I204: Arthrex | J204: Medical Devices | K204: Camarillo, California, United States | L204: arthrex.com | M204: https://www.linkedin.com/in/willlucas1/
A205: Gnanendra Gopal | B205: Gnanendra | C205: Gopal | D205: Software and Diagnostics - Customer Quality Engineer | E205: Engineer | F205: 10 | G205: B | H205: 64 | I205: Ather Energy | J205: Medical Devices | K205: Bengaluru South, Karnataka, India | L205: atherenergy.com | M205: https://www.linkedin.com/in/gnanendragopal/
A206: Jonathon Elliott | B206: Jonathon | C206: Elliott | D206: Quality Engineer | E206: Engineer | F206: 10 | G206: B | H206: 64 | I206: Baxter Enterprises / Baxter Manufacturing | J206: Medical Devices | K206: Greenville-Spartanburg-Anderson, South Carolina Area | L206: baxterent.com | M206: https://www.linkedin.com/in/jonathon-elliott-382031171/
A207: Arun Mathew | B207: Arun | C207: Mathew | D207: Quality Engineer | E207: Engineer | F207: 10 | G207: B | H207: 64 | I207: Baylis Medical Technologies | J207: Medical Devices | K207: Oshawa, Ontario, Canada | L207: baylismedtech.com | M207: https://www.linkedin.com/in/arun-mathew-28384ba9/
A208: Dhruv Modi | B208: Dhruv | C208: Modi | D208: Manufacturing Quality Engineer | E208: Engineer | F208: 10 | G208: B | H208: 64 | I208: BD | J208: Medical Devices | K208: San Diego, California, United States | L208: bd.com | M208: https://www.linkedin.com/in/dhruv-modi9/
... A289: Carlos Finger | B289: Carlos | C289: Finger | D289: Analista de Qualidade Pleno | E289: Other | F289: 12 | G289: C | H289: 45 | I289: Taurus Armas | J289: Medical Devices | K289: Novo Hamburgo, Rio Grande do Sul, Brazil | L289: taurusarmas.com.br | M289: https://www.linkedin.com/in/carlos-finger-455847b3/

Sheet Industrial Equipment
A1: Full Name | B1: First Name | C1: Last Name | D1: Job Title | E1: Seniority Level | F1: Seniority Rank | G1: Lead Score | H1: Opportunity Score | I1: Company Name | J1: Industry | K1: Location | L1: Company Domain | M1: LinkedIn Profile | N1: Phone | O1: Email/Gmail | P1: Follow Up 1 | Q1: Follow Up 2 | R1: Follow Up 3 | S1: Follow Up 4 | T1: Follow Up 5 | U1: Email 1 | V1: Email 2 | W1: Email 3 | X1: Email 4 | Y1: Email 5 | Z1: Cold Call 1 | AA1: Cold Call 2 | AB1: Cold Call 3 | AC1: Meeting | AD1: RFQ | AE1: Quote | AF1: Won | AG1: Lost | AH1: Outcome Status | AI1: Rejection Reason | AJ1: Interest Reason | AK1: Notes | AL1: First Contact | AM1: Last Contact | AN1: Next Follow-up
A2: Andrew Mendez | B2: Andrew | C2: Mendez | D2: President | Senior Buyer | E2: C-Level | F2: 1 | G2: A+ | H2: 100 | I2: Blackstone Machinery | J2: Industrial Equipment | K2: Cerritos, California, United States | L2: blackstonemachinery.com | M2: https://www.linkedin.com/in/andrewmendez21/
A3: Mugo Wanjohi | B3: Mugo | C3: Wanjohi | D3: Senior sales associate used machinery, Digital marketing head , chief buyer | E3: C-Level | F3: 1 | G3: A+ | H3: 100 | I3: Machine 4 Africa LTD. | J3: Industrial Equipment | K3: Kenya | L3: machine4africa.com | M3: https://www.linkedin.com/in/mugo-wanjohi-55622b1b/
A4: Belinda T. | B4: Belinda | C4: T. | D4: Sourcing Manager - Strategic Commodity Management | E4: Manager | F4: 6 | G4: A+ | H4: 94 | I4: 3M | J4: Industrial Equipment | K4: Singapore | L4: mmm.com | M4: https://www.linkedin.com/in/belinda-t-48321459/
A5: Ryan Grant | B5: Ryan | C5: Grant | D5: Senior Global Sourcing Manager | E5: Manager | F5: 6 | G5: A+ | H5: 94 | I5: AirLife | J5: Industrial Equipment | K5: Greater Pittsburgh Region | L5: myairlife.com | M5: https://www.linkedin.com/in/ryan-grant-1a64663a/
A6: Claus Møller | B6: Claus | C6: Møller | D6: Global Purchasing Manager | E6: Manager | F6: 6 | G6: A+ | H6: 94 | I6: Alfa Laval | J6: Industrial Equipment | K6: Greater Malmö Metropolitan Area, Sweden | L6: alfalaval.com | M6: https://www.linkedin.com/in/claus-m%c3%b8ller-3a6b6a8/
A7: Terje Klyver | B7: Terje | C7: Klyver | D7: Global Purchasing Manager | E7: Manager | F7: 6 | G7: A+ | H7: 94 | I7: Alfa Laval | J7: Industrial Equipment | K7: Tumba, Stockholm County, Sweden | L7: alfalaval.com | M7: https://www.linkedin.com/in/terje-klyver-7800503/
A8: Renê Bajo | B8: Renê | C8: Bajo | D8: USA Purchasing Manager - HOY Compressor Division | E8: Manager | F8: 6 | G8: A+ | H8: 94 | I8: Atlas Copco | J8: Industrial Equipment | K8: Fort Mill, South Carolina, United States | L8: atlascopco.com | M8: https://www.linkedin.com/in/renê-bajo-b826b874/
A9: Hauke Hans | B9: Hauke | C9: Hans | D9: Leiter Einkauf / Purchasing Manager | E9: Manager | F9: 6 | G9: A+ | H9: 94 | I9: Atlas Copco Group | J9: Industrial Equipment | K9: Neustadt an der Donau, Bavaria, Germany | L9: atlascopcogroup.com | M9: https://www.linkedin.com/in/hauke-hans-75a76916/
A10: Romain Boré | B10: Romain | C10: Boré | D10: Procurement Manager - Pipe, fittings and structural steel | E10: Manager | F10: 6 | G10: A+ | H10: 94 | I10: Boccard | J10: Industrial Equipment | K10: Sillingy, Auvergne-Rhône-Alpes, France | L10: boccard.com | M10: https://www.linkedin.com/in/romain-bore/
A11: Andrew Moore | B11: Andrew | C11: Moore | D11: Global Procurement Manager | E11: Manager | F11: 6 | G11: A+ | H11: 94 | I11: Caterpillar Inc. | J11: Industrial Equipment | K11: Mossville, Illinois, United States | L11: caterpillar.com | M11: https://www.linkedin.com/in/andrew-moore-048aa/
A12: Baljinder Singh | B12: Baljinder | C12: Singh | D12: Procurement Manager | E12: Manager | F12: 6 | G12: A+ | H12: 94 | I12: Caterpillar Inc. | J12: Industrial Equipment | K12: Tucson, Arizona, United States | L12: caterpillar.com | M12: https://www.linkedin.com/in/baljinder-singh-52bb2a36/
A13: Cynthia Rogers | B13: Cynthia | C13: Rogers | D13: Procurement Manager, Fasteners | E13: Manager | F13: 6 | G13: A+ | H13: 94 | I13: Caterpillar Inc. | J13: Industrial Equipment | K13: Peoria Metropolitan Area | L13: caterpillar.com | M13: https://www.linkedin.com/in/cynrogers/
... A48: swapnil kulkarni | B48: Swapnil | C48: Kulkarni | D48: Procurement Manager | E48: Manager | F48: 6 | G48: A+ | H48: 94 | I48: Kirloskar Brothers Limited | J48: Industrial Equipment | K48: Pune, Maharashtra, India | L48: kirloskarpumps.com | M48: https://www.linkedin.com/in/swapnil-kulkarni-14183a1b/
A49: 杨瑞霞Vivien | B49: Vivien | D49: Purchasing Manager | E49: Manager | F49: 6 | G49: A+ | H49: 94 | I49: Lei Shing Hong Machinery | J49: Industrial Equipment | K49: Shanghai, China | L49: lsh-ppower.com | M49: https://www.linkedin.com/in/vivien-杨瑞霞-674b6116/
A50: Karla Mayela Ruiz Meza | B50: Karla | C50: Meza | D50: Commodity Manager CVP North America | E50: Manager | F50: 6 | G50: A+ | H50: 94 | I50: Littelfuse | J50: Industrial Equipment | K50: San Luis Potosí, San Luis Potosí, México | L50: littelfuse.com | M50: https://www.linkedin.com/in/karla-mayela-ruiz-meza-62717161/
A51: Anand Khedkar | B51: Anand | C51: Khedkar | D51: Strategic Sourcing Manager | E51: Manager | F51: 6 | G51: A+ | H51: 94 | I51: Mahindra and Mahindra Limited [Automotive and Farm Equipment Business] | J51: Industrial Equipment | K51: Mumbai, Maharashtra, India | L51: mahindracareers.com | M51: https://www.linkedin.com/in/anand-khedkar-12ba88b7/
A52: Arshad shaikh | B52: Arshad | C52: shaikh | D52: Assistant Purchasing Manager | E52: Manager | F52: 6 | G52: A+ | H52: 94 | I52: Mahindra and Mahindra Limited [Automotive and Farm Equipment Business] | J52: Industrial Equipment | K52: Pune District, Maharashtra, India | L52: mahindracareers.com | M52: https://www.linkedin.com/in/arshad-shaikh-336025111/
A53: Mahesh Jatte | B53: Mahesh | C53: Jatte | D53: Assistant Manager - SCM Buyer | E53: Manager | F53: 6 | G53: A+ | H53: 94 | I53: Mahindra and Mahindra Limited [Automotive and Farm Equipment Business] | J53: Industrial Equipment | K53: Mumbai, Maharashtra, India | L53: mahindracareers.com | M53: https://www.linkedin.com/in/mahesh-jatte-b57810211/
A54: Syed Z. | B54: Syed | C54: Z. | D54: Cost Engineering & Strategic Sourcing Manager | E54: Manager | F54: 6 | G54: A+ | H54: 94 | I54: Mahindra and Mahindra Limited [Automotive and Farm Equipment Business] | J54: Industrial Equipment | K54: Bengaluru, Karnataka, India | L54: mahindracareers.com | M54: https://www.linkedin.com/in/syed-z-b381057a/
A55: André Lopes | B55: André | C55: Lopes | D55: Sourcing Manager (Strategic Team) | E55: Manager | F55: 6 | G55: A+ | H55: 94 | I55: Metso | J55: Industrial Equipment | K55: São Bernardo do Campo, São Paulo, Brazil | L55: metso.com | M55: https://www.linkedin.com/in/andr%c3%a9-lopes-06464190/
A56: Anu Penttinen | B56: Anu | C56: Penttinen | D56: Project Procurement Manager | E56: Manager | F56: 6 | G56: A+ | H56: 94 | I56: Metso | J56: Industrial Equipment | K56: Helsinki, Uusimaa, Finland | L56: metso.com | M56: https://www.linkedin.com/in/anu-penttinen/
A57: Gokhan Santurkaya | B57: Gokhan | C57: Santurkaya | D57: Global Mill Lining Procurement Manager | E57: Manager | F57: 6 | G57: A+ | H57: 94 | I57: Metso | J57: Industrial Equipment | K57: Ankara, Turkey | L57: metso.com | M57: https://www.linkedin.com/in/gokhan-santurkaya-61428261/
A58: Vesa Nieminen | B58: Vesa | C58: Nieminen | D58: Global Category Sourcing Manager | E58: Manager | F58: 6 | G58: A+ | H58: 94 | I58: Metso | J58: Industrial Equipment | K58: Helsinki, Uusimaa, Finland | L58: metso.com | M58: https://www.linkedin.com/in/vesa-nieminen-1a567764/
A59: Tarun Shankar | B59: Tarun | C59: Shankar | D59: Sourcing Manager | E59: Manager | F59: 6 | G59: A+ | H59: 94 | I59: Metso Outotec | J59: Industrial Equipment | K59: Surat, Gujarat, India | L59: mogroup.com | M59: https://www.linkedin.com/in/tarun-shankar-0b664438/
A60: Andre Coenen | B60: Andre | C60: Coenen | D60: Purchasing Manager | E60: Manager | F60: 6 | G60: A+ | H60: 94 | I60: Nedschroef Machinery | J60: Industrial Equipment | K60: Kuringen, Flemish Region, Belgium | L60: nedschroefmachinery.com | M60: https://www.linkedin.com/in/coenenandre/
A61: Romain Chies | B61: Romain | C61: Chies | D61: Global Indirect Purchasing Manager | E61: Manager | F61: 6 | G61: A+ | H61: 94 | I61: OPmobility | J61: Industrial Equipment | K61: Brittany, France | L61: opmobility.com | M61: https://www.linkedin.com/in/romain-chies/
... A105: Michael Traber | B105: Michael | C105: Traber | D105: Senior Buyer | E105: Senior | F105: 8 | G105: A | H105: 88 | I105: ITT Flow Technologies | J105: Industrial Equipment | K105: Houston, Texas, United States | L105: itt.com | M105: https://www.linkedin.com/in/michael-traber-023bb0b/
A106: Noel Soliva | B106: Noel | C106: Soliva | D106: Sr. Strategic Buyer - OSAT Procurement | E106: Senior | F106: 8 | G106: A | H106: 88 | I106: Littelfuse Phils, Inc. | J106: Industrial Equipment | K106: Cebu, Central Visayas, Philippines | M106: https://www.linkedin.com/in/noel-soliva-4a22367/
A107: Cynthia Falone | B107: Cynthia | C107: Falone | D107: Senior Buyer | E107: Senior | F107: 8 | G107: A | H107: 88 | I107: Milton Roy, An Ingersoll Rand Business | J107: Industrial Equipment | K107: Warminster, Pennsylvania, United States | L107: miltonroy.com | M107: https://www.linkedin.com/in/cynthia-falone-6643047/
A108: Luis Ferraz | B108: Luis | C108: Ferraz | D108: Capital Equipment Senior Buyer | E108: Senior | F108: 8 | G108: A | H108: 88 | I108: Molex | J108: Industrial Equipment | K108: Detroit Metropolitan Area, United States | L108: molex.com | M108: https://www.linkedin.com/in/luis-felipe-fregonezi-ferraz/
A109: William P. Mahoney, Jr. | B109: William | C109: Mahoney | D109: Senior Buyer | E109: Senior | F109: 8 | G109: A | H109: 88 | I109: Parker Hannifin | J109: Industrial Equipment | K109: Greater Boston | L109: parker.com | M109: https://www.linkedin.com/in/william-p-mahoney-jr-671368126/
A110: Guilherme Piwowarczyk Reis | B110: Guilherme | C110: Reis | D110: Senior Buyer | E110: Senior | F110: 8 | G110: A | H110: 88 | I110: Sulzer | J110: Industrial Equipment | K110: Jundiaí, São Paulo, Brazil | L110: sulzer.com | M110: https://www.linkedin.com/in/guipiworeis/
A111: Filip Heimerle | B111: Filip | C111: Heimerle | D111: Senior buyer | E111: Senior | F111: 8 | G111: A | H111: 88 | I111: WITTE Automotive | J111: Industrial Equipment | K111: Karlovy Vary, Czechia | L111: witte-automotive.com | M111: https://www.linkedin.com/in/filip-heimerle-994b2216/
A112: Tanmay Gupta | B112: Tanmay | C112: Gupta | D112: Senior Quality Engineer | E112: Senior | F112: 8 | G112: B | H112: 68 | I112: Atlas Copco Group | J112: Industrial Equipment | K112: Pune Division, Maharashtra, India | L112: atlascopcogroup.com | M112: https://www.linkedin.com/in/tanmay-gupta-575a0556/
A113: J.R. Plote | B113: J.R. | C113: Plote | D113: Senior Quality Engineer | E113: Senior | F113: 8 | G113: B | H113: 68 | I113: Eaton | J113: Industrial Equipment | K113: Greater Milwaukee, United States | L113: eaton.com | M113: https://www.linkedin.com/in/j-r-plote-27b5aa11a/
A114: Anton Zemleroub | B114: Anton | C114: Zemleroub | D114: Senior Quality Engineer | E114: Senior | F114: 8 | G114: B | H114: 68 | I114: Foxconn Industrial Internet - FII | J114: Industrial Equipment | K114: San Jose, California, United States | L114: applytojob.com | M114: https://www.linkedin.com/in/anton-zemleroub-01193b12/
A115: Gayathri V. | B115: Gayathri | C115: V. | D115: Senior Quality Engineer – Data & AI Automation (SDET) | E115: Senior | F115: 8 | G115: B | H115: 68 | I115: IQVIA | J115: Industrial Equipment | K115: Plano, Texas, United States | L115: iqvia.com | M115: https://www.linkedin.com/in/gvemuri4/
A116: Mayank Mishra | B116: Mayank | C116: Mishra | D116: Senior Quality Engineer | E116: Senior | F116: 8 | G116: B | H116: 68 | I116: Metso | J116: Industrial Equipment | K116: Alwar, Rajasthan, India | L116: metso.com | M116: https://www.linkedin.com/in/mayank-mishra-371785229/
A117: Logan Mulderrig | B117: Logan | C117: Mulderrig | D117: Senior Quality Assurance Engineer | E117: Senior | F117: 8 | G117: B | H117: 68 | I117: Pentair | J117: Industrial Equipment | K117: Raleigh, North Carolina, United States | L117: pentair.com | M117: https://www.linkedin.com/in/loganmulderrig/
...

Sheet HVAC Appliances
A1: Full Name | B1: First Name | C1: Last Name | D1: Job Title | E1: Seniority Level | F1: Seniority Rank | G1: Lead Score | H1: Opportunity Score | I1: Company Name | J1: Industry | K1: Location | L1: Company Domain | M1: LinkedIn Profile | N1: Phone | O1: Email/Gmail | P1: Follow Up 1 | Q1: Follow Up 2 | R1: Follow Up 3 | S1: Follow Up 4 | T1: Follow Up 5 | U1: Email 1 | V1: Email 2 | W1: Email 3 | X1: Email 4 | Y1: Email 5 | Z1: Cold Call 1 | AA1: Cold Call 2 | AB1: Cold Call 3 | AC1: Meeting | AD1: RFQ | AE1: Quote | AF1: Won | AG1: Lost | AH1: Outcome Status | AI1: Rejection Reason | AJ1: Interest Reason | AK1: Notes | AL1: First Contact | AM1: Last Contact | AN1: Next Follow-up
A2: Ghanashyam T | B2: Ghanashyam | C2: T | D2: Sourcing Manager | E2: Manager | F2: 6 | G2: A+ | H2: 94 | I2: A.O. Smith India | J2: HVAC Appliances | K2: Bengaluru, Karnataka, India | L2: aosmithindia.com | M2: https://www.linkedin.com/in/ghanashyam-t-52a79621/
A3: Susan Siegel | B3: Susan | C3: Siegel | D3: Group Commodity Manager, Indirect | E3: Manager | F3: 6 | G3: A+ | H3: 94 | I3: Broan-NuTone | J3: HVAC Appliances | K3: New York City Metropolitan Area, United States | L3: broan-nutone.com | M3: https://www.linkedin.com/in/susan-siegel/
A4: Gülhande AYDIN | B4: Gülhande | C4: AYDIN | D4: Commodity Manager | E4: Manager | F4: 6 | G4: A+ | H4: 94 | I4: BSH Home Appliances Group | J4: HVAC Appliances | K4: Turkey | L4: bsh-group.com | M4: https://www.linkedin.com/in/g%c3%bclhande-aydin-722371a8/
A5: Serkan Burak YILDIRIM | B5: Serkan | C5: YILDIRIM | D5: Purchasing Manager | E5: Manager | F5: 6 | G5: A+ | H5: 94 | I5: BSH Home Appliances Group | J5: HVAC Appliances | K5: Greenville-Washington, North Carolina Area | L5: bsh-group.com | M5: https://www.linkedin.com/in/serkan-burak-yildirim-b1081535/
A6: Roberto Najera Flores | B6: Roberto | C6: Flores | D6: Strategic Sourcing Manager | E6: Manager | F6: 6 | G6: A+ | H6: 94 | I6: Daikin Applied Americas | J6: HVAC Appliances | K6: Nuevo León, Mexico | L6: daikinapplied.com | M6: https://www.linkedin.com/in/roberto-najera-flores-b0b20258/
A7: Milton J. SEGOVIA | B7: Milton | C7: SEGOVIA | D7: Senior Commodity Manager | E7: Manager | F7: 6 | G7: A+ | H7: 94 | I7: Daikin Comfort | J7: HVAC Appliances | K7: Monterrey Metropolitan Area | L7: daikincomfort.com | M7: https://www.linkedin.com/in/msegovia132628/
A8: Rakesh Sethukumar | B8: Rakesh | C8: Sethukumar | D8: Strategic Sourcing Manager | E8: Manager | F8: 6 | G8: A+ | H8: 94 | I8: Danfoss | J8: HVAC Appliances | K8: Scarborough, Ontario, Canada | L8: danfoss.com | M8: https://www.linkedin.com/in/rakeshsethu/
A9: Bhanudas Patil | B9: Bhanudas | C9: Patil | D9: Global Sourcing Manager | E9: Manager | F9: 6 | G9: A+ | H9: 94 | I9: Danfoss Power Solutions | J9: HVAC Appliances | K9: Pune Division, Maharashtra, India | L9: danfoss.com | M9: https://www.linkedin.com/in/bhanudas-patil-a56a2963/
A10: Roger Rieckers | B10: Roger | C10: Rieckers | D10: Senior Commodity Manager | E10: Manager | F10: 6 | G10: A+ | H10: 94 | I10: GE Appliances, a Haier company | J10: HVAC Appliances | K10: New Albany, Indiana, United States | L10: geappliancesco.com | M10: https://www.linkedin.com/in/roger-rieckers/
A11: Kerim Tulgar | B11: Kerim | C11: Tulgar | D11: Procurement Manager | E11: Manager | F11: 6 | G11: A+ | H11: 94 | I11: Haier Europe | J11: HVAC Appliances | K11: Eskişehir, Turkey | L11: haier-europe.com | M11: https://www.linkedin.com/in/kerim-tulgar-a014918b/
A12: Riccardo Granata | B12: Riccardo | C12: Granata | D12: Global Commodity Manager Transformation & Strategic Components | E12: Manager | F12: 6 | G12: A+ | H12: 94 | I12: Haier Europe | J12: HVAC Appliances | K12: Corbetta, Lombardy, Italy | L12: haier-europe.com | M12: https://www.linkedin.com/in/riccardogranata/
A13: Paweł Nośko | B13: Paweł | C13: Nośko | D13: Procurement Manager Capital and Tooling | E13: Manager | F13: 6 | G13: A+ | H13: 100 | I13: KIRCHHOFF Automotive | J13: HVAC Appliances | K13: Mielecki, Podkarpackie, Poland | L13: kirchhoff-automotive.com | M13: https://www.linkedin.com/in/paweł-nośko-72b64212a/
... A81: Sabine Hantke | B81: Sabine | C81: Hantke | D81: Einkäuferin | E81: Other | F81: 12 | G81: C | H81: 45 | I81: Miele | J81: HVAC Appliances | K81: Gütersloh, North Rhine-Westphalia, Germany | L81: miele.com | M81: https://www.linkedin.com/in/sabine-hantke-0ab738236/

Sheet Packaging
A1: Full Name | B1: First Name | C1: Last Name | D1: Job Title | E1: Seniority Level | F1: Seniority Rank | G1: Lead Score | H1: Opportunity Score | I1: Company Name | J1: Industry | K1: Location | L1: Company Domain | M1: LinkedIn Profile | N1: Phone | O1: Email/Gmail | P1: Follow Up 1 | Q1: Follow Up 2 | R1: Follow Up 3 | S1: Follow Up 4 | T1: Follow Up 5 | U1: Email 1 | V1: Email 2 | W1: Email 3 | X1: Email 4 | Y1: Email 5 | Z1: Cold Call 1 | AA1: Cold Call 2 | AB1: Cold Call 3 | AC1: Meeting | AD1: RFQ | AE1: Quote | AF1: Won | AG1: Lost | AH1: Outcome Status | AI1: Rejection Reason | AJ1: Interest Reason | AK1: Notes | AL1: First Contact | AM1: Last Contact | AN1: Next Follow-up | AO1: Lead Warmth Level | AP1: Priority | AQ1: Recommended Channel | AR1: Current Stage | AS1: Value Proposition | AT1: Pain Point
A2: KC Christensen | B2: KC | C2: Christensen | D2: CEO Used Equipment Buyer Packaging Specialist Investment Recovery | E2: C-Level | F2: 1 | G2: A+ | H2: 100 | I2: Aaron Kendell Packaging Equipment (AEK) | J2: Packaging | K2: Belvidere, Illinois, United States | L2: aekpack.com | M2: https://www.linkedin.com/in/kcchristensen1/
A3: Ken Stevens | B3: Ken | C3: Stevens | D3: Sr. Director Sourcing & Procurement ; sr. Group Sourcing Manager Mech. assies, tooling & packaging | E3: Director | F3: 4 | G3: A+ | H3: 100 | I3: ASML | J3: Packaging | K3: Kalmthout, Flemish Region, Belgium | L3: asml.com | M3: https://www.linkedin.com/in/ken-stevens-a5386568/
A4: Naree Ferreira | B4: Naree | C4: Ferreira | D4: Global Sourcing Manager Packaging Strategic Projects | E4: Manager | F4: 6 | G4: A+ | H4: 94 | I4: AB InBev | J4: Packaging | K4: Leuven, Flemish Region, Belgium | L4: ab-inbev.com | M4: https://www.linkedin.com/in/naree-ferreira-20210324/
A5: Sonia Sánchez Baena | B5: Sonia | C5: Baena | D5: Packaging procurement manager | E5: Manager | F5: 6 | G5: A+ | H5: 94 | I5: AB InBev | J5: Packaging | K5: Mexico City, Mexico | L5: ab-inbev.com | M5: https://www.linkedin.com/in/sonia-sánchez-baena-b3354810a/
A6: Tanja Caddell | B6: Tanja | C6: Caddell | D6: Sr. Commodity Manager, Packaging, Mgr. of team for Fasteners, Machined Parts & Springs | E6: Manager | F6: 6 | G6: A+ | H6: 94 | I6: Allegion | J6: Packaging | K6: Colorado Springs, Colorado, United States | L6: allegion.com | M6: https://www.linkedin.com/in/tanja-caddell-277a1310/
A7: Milena Nagamine | B7: Milena | C7: Nagamine | D7: Senior Procurement Manager | Raw Materials, Components, Packaging & Outsourcing | E7: Manager | F7: 6 | G7: A+ | H7: 94 | I7: Alpargatas S.A. | J7: Packaging | K7: São Paulo e Região | L7: alpargatas.com.br | M7: https://www.linkedin.com/in/milena-nagamine-a48b2344/
A8: Nuria Teran | B8: Nuria | C8: Teran | D8: Purchasing Manager Metal, Fasteners & Packaging EMEA & ASIA | E8: Manager | F8: 6 | G8: A+ | H8: 94 | I8: Antolin | J8: Packaging | K8: Greater Burgos Metropolitan Area | L8: antolin.com | M8: https://www.linkedin.com/in/nuria-teran-8071a69/
A9: Erkan Gunes | B9: Erkan | C9: Gunes | D9: Purchasing Manager | E9: Manager | F9: 6 | G9: A+ | H9: 94 | I9: Apack Packaging Technologies | J9: Packaging | K9: Istanbul, Turkey | L9: apack.com.tr | M9: https://www.linkedin.com/in/erkan-gunes-16ab0716b/
A10: Paulo Gurita | B10: Paulo | C10: Gurita | D10: Purchasing Manager BAC (Brazil, Argentina & Chile) | E10: Manager | F10: 6 | G10: A+ | H10: 94 | I10: Avery Dennison Label and Packaging Materials | J10: Packaging | K10: Greater Campinas | L10: averydennison.com | M10: https://www.linkedin.com/in/paulo-gurita-55723513/
A11: Melisa Devichund | B11: Melisa | C11: Devichund | D11: Procurement Manager- Packaging | E11: Manager | F11: 6 | G11: A+ | H11: 94 | I11: AVI Limited | J11: Packaging | K11: City of Johannesburg, Gauteng, South Africa | L11: avi.co.za | M11: https://www.linkedin.com/in/melisa-sukku-52a58535/
A12: Marcio Remor, MBA, SCPro | B12: Marcio | C12: SCPro | D12: Strategic Sourcing Manager - Packaging | E12: Manager | F12: 6 | G12: A+ | H12: 94 | I12: Barr Brands | J12: Packaging | K12: Collierville, Tennessee, United States | L12: barrbrands.com | M12: https://www.linkedin.com/in/marcio-remor-mba-scpro-26162835/
A13: Alejandro Parodi | B13: Alejandro | C13: Parodi | D13: Global Procurement Manager Logistics & Packaging | E13: Manager | F13: 6 | G13: A+ | H13: 94 | I13: Bekaert | J13: Packaging | K13: Leuven, Flemish Region, Belgium | L13: bekaert.com | M13: https://www.linkedin.com/in/alejandro-parodi/
... A250: Weslei Coimbra | B250: Weslei | C250: Coimbra | D250: Comprador | E250: Other | F250: 12 | G250: C | H250: 45 | I250: ULMA Packaging Brasil | J250: Packaging | K250: Santa Bárbara d'Oeste, São Paulo, Brazil | L250: ulmapackaging.com.br | M250: https://www.linkedin.com/in/weslei-coimbra-011654181/
A251: Bruno Pack | B251: Bruno | C251: Pack | D251: Senior Buyer | E251: Senior | F251: 7 | I251: Tetra Pak | J251: Packaging | AH251: Active | AO251: Frío | AP251: Media | AQ251: LinkedIn | AR251: Nuevo lead

Sheet Consumer Goods
A1: Full Name | B1: First Name | C1: Last Name | D1: Job Title | E1: Seniority Level | F1: Seniority Rank | G1: Lead Score | H1: Opportunity Score | I1: Company Name | J1: Industry | K1: Location | L1: Company Domain | M1: LinkedIn Profile | N1: Phone | O1: Email/Gmail | P1: Follow Up 1 | Q1: Follow Up 2 | R1: Follow Up 3 | S1: Follow Up 4 | T1: Follow Up 5 | U1: Email 1 | V1: Email 2 | W1: Email 3 | X1: Email 4 | Y1: Email 5 | Z1: Cold Call 1 | AA1: Cold Call 2 | AB1: Cold Call 3 | AC1: Meeting | AD1: RFQ | AE1: Quote | AF1: Won | AG1: Lost | AH1: Outcome Status | AI1: Rejection Reason | AJ1: Interest Reason | AK1: Notes | AL1: First Contact | AM1: Last Contact | AN1: Next Follow-up
A2: Sebastien Aumiaux | B2: Sebastien | C2: Aumiaux | D2: Group Chief Procurement Officer | E2: C-Level | F2: 1 | G2: A+ | H2: 93 | I2: Cooper Consumer Health | J2: Consumer Goods | K2: Bordeaux, Nouvelle-Aquitaine, France | L2: cooperconsumerhealth.com | M2: https://www.linkedin.com/in/sebastien-aumiaux-3972973/
A3: Shailendra Sadera | B3: Shailendra | C3: Sadera | D3: Chief Procurement Officer | E3: C-Level | F3: 1 | G3: A+ | H3: 93 | I3: Unilever | J3: Consumer Goods | K3: London, England, United Kingdom | L3: unilever.com | M3: https://www.linkedin.com/in/shailendra-sadera-64a5171/
A4: Sharon Wang | B4: Sharon | C4: Wang | D4: Sourcing Manager - Plastics Engineering | E4: Manager | F4: 6 | G4: A+ | H4: 100 | I4: Newell Brands | J4: Consumer Goods | K4: Charlotte, North Carolina, United States | L4: newellbrands.com | M4: https://www.linkedin.com/in/sharon-wang-635451124/
A5: Rawan El-Ashkar | B5: Rawan | C5: El-Ashkar | D5: Senior purchasing manager for Fabric care injection molding NA | E5: Manager | F5: 6 | G5: A+ | H5: 100 | I5: Procter & Gamble | J5: Consumer Goods | K5: Cincinnati, Ohio, United States | L5: pg.com | M5: https://www.linkedin.com/in/rawanelashkar/
A6: Thomas Delfau | B6: Thomas | C6: Delfau | D6: Senior Purchasing Manager - EU Resins and Masterbatches | E6: Manager | F6: 6 | G6: A+ | H6: 100 | I6: Procter & Gamble | J6: Consumer Goods | K6: Geneva, Switzerland | L6: pg.com | M6: https://www.linkedin.com/in/thomas-delfau-2b89825a/
A7: Richard Chin | B7: Richard | C7: Chin | D7: Sourcing Manager (Colorants, Additives, Inks, Injection Molding) | E7: Manager | F7: 6 | G7: A+ | H7: 100 | I7: Reynolds Consumer Products | J7: Consumer Goods | K7: Greater Chicago Area | L7: reynoldsconsumerproducts.com | M7: https://www.linkedin.com/in/richard-chin-a1781564/
A8: Victor de Lima Spilleir | B8: Victor | C8: de Lima Spilleir | D8: Procurement Manager - Rigid Plastics & Electrical Devices | E8: Manager | F8: 6 | G8: A+ | H8: 100 | I8: SC Johnson | J8: Consumer Goods | K8: Rio de Janeiro, Brazil | L8: scjohnson.com | M8: https://www.linkedin.com/in/victor-de-lima-spilleir-28b389156/
A9: Nico Febriady | B9: Nico | C9: Febriady | D9: Global Procurement Manager Plastics Sustainability | E9: Manager | F9: 6 | G9: A+ | H9: 100 | I9: Unilever | J9: Consumer Goods | K9: Indonesia, Indonesia | L9: unilever.com | M9: https://www.linkedin.com/in/nico-febriady-04974b4b/
A10: Veeresh Kotagi | B10: Veeresh | C10: Kotagi | D10: Global Assistant Procurement Manager – Injection Moulds & Rigids | E10: Manager | F10: 6 | G10: A+ | H10: 100 | I10: Unilever | J10: Consumer Goods | K10: Mumbai, Maharashtra, India | L10: unilever.com | M10: https://www.linkedin.com/in/veeresh-kotagi-b33990198/
A11: Venugopal (Venu) Reddy | B11: Venugopal | C11: Reddy | D11: Procurement Manager - Plastics Sustainability | Analytics | Reporting | Assurance | E11: Manager | F11: 6 | G11: A+ | H11: 100 | I11: Unilever | J11: Consumer Goods | K11: Mumbai, Maharashtra, India | L11: unilever.com | M11: https://www.linkedin.com/in/venugopal-venu-reddy-9b717618/
A12: Binod GC | B12: Binod | C12: GC | D12: Regional Procurement Manager at Coca-Cola beverages Nepal | E12: Manager | F12: 6 | G12: A | H12: 87 | I12: Coca-Cola Beverages Nepal | J12: Consumer Goods | K12: Bharatpur, Nepal | L12: bnl.com.np | M12: https://www.linkedin.com/in/binod-gc-64534960/
A13: Morgan Chatelain | B13: Morgan | C13: Chatelain | D13: Capital Equipment Procurement Manager | E13: Manager | F13: 6 | G13: A | H13: 87 | I13: Coca-Cola Europacific Partners | J13: Consumer Goods | K13: Paris, Île-de-France, France | L13: cocacolaep.com | M13: https://www.linkedin.com/in/morgan-chatelain-581b1a105/
